<?xml version="1.0"?>
<!-- created with Phobos 1.0.1 "Capricious Choutengan" -->
  <robot name="Kitchen_standard">

    <link name="GlassBottle_root">
      <inertial>
        <origin xyz="0 0 0" rpy="0 0 0"/>
        <mass value="0.2268"/>
        <inertia ixx="0.001" ixy="0" ixz="0" iyy="0.001" iyz="0" izz="0.001"/>
      </inertial>
      <visual name="GlassBottle">
        <origin xyz="0 0 0" rpy="0 0 0"/>
        <geometry>
          <mesh filename="package://Kitchen_standard/meshes/dae/GlassBottle.dae" scale="0.00114 0.00114 0.00114"/>
        </geometry>
        <material name="__Blue_Glass_"/>
      </visual>
      <collision name="GlassBottle.col">
        <origin xyz="0 0 0" rpy="0 0 0"/>
        <geometry>
          <mesh filename="package://Kitchen_standard/meshes/dae/GlassBottle.001.dae" scale="1.0 1.0 1.0"/>
        </geometry>
      </collision>
    </link>

    <link name="Glass_root">
      <inertial>
        <origin xyz="0 0 0" rpy="0 0 0"/>
        <mass value="0.14"/>
        <inertia ixx="0.00082" ixy="0" ixz="0" iyy="0.00082" iyz="0" izz="0.00015"/>
      </inertial>
      <visual name="Glass">
        <origin xyz="0 0 0" rpy="0 0 0"/>
        <geometry>
          <mesh filename="package://Kitchen_standard/meshes/dae/Glass.dae" scale="1.0 1.0 1.0"/>
        </geometry>
        <material name="Glass"/>
      </visual>
      <collision name="Glass.col">
        <origin xyz="0 0 0" rpy="0 0 0"/>
        <geometry>
          <mesh filename="package://Kitchen_standard/meshes/dae/Glass.002.dae" scale="1.0 1.0 1.0"/>
        </geometry>
      </collision>
    </link>

    <link name="Glass_root.001">
      <inertial>
        <origin xyz="0 0 0" rpy="0 0 0"/>
        <mass value="0.14"/>
        <inertia ixx="0.00082" ixy="0" ixz="0" iyy="0.00082" iyz="0" izz="0.00015"/>
      </inertial>
      <visual name="Glass.001">
        <origin xyz="0 0 0" rpy="0 0 0"/>
        <geometry>
          <mesh filename="package://Kitchen_standard/meshes/dae/Glass.003.dae" scale="1.0 1.0 1.0"/>
        </geometry>
        <material name="Glass"/>
      </visual>
      <collision name="Glass.col.001">
        <origin xyz="0 0 0" rpy="0 0 0"/>
        <geometry>
          <mesh filename="package://Kitchen_standard/meshes/dae/Glass.001.dae" scale="1.0 1.0 1.0"/>
        </geometry>
      </collision>
    </link>

    <link name="Glass_root.002">
      <inertial>
        <origin xyz="0 0 0" rpy="0 0 0"/>
        <mass value="0.14"/>
        <inertia ixx="0.00082" ixy="0" ixz="0" iyy="0.00082" iyz="0" izz="0.00015"/>
      </inertial>
      <visual name="Glass.002">
        <origin xyz="0 0 0" rpy="0 0 0"/>
        <geometry>
          <mesh filename="package://Kitchen_standard/meshes/dae/Glass.004.dae" scale="1.0 1.0 1.0"/>
        </geometry>
        <material name="Glass"/>
      </visual>
      <collision name="Glass.col.002">
        <origin xyz="0 0 0" rpy="0 0 0"/>
        <geometry>
          <mesh filename="package://Kitchen_standard/meshes/dae/Glass.005.dae" scale="1.0 1.0 1.0"/>
        </geometry>
      </collision>
    </link>

    <link name="Glass_root.003">
      <inertial>
        <origin xyz="0 0 0" rpy="0 0 0"/>
        <mass value="0.14"/>
        <inertia ixx="0.00082" ixy="0" ixz="0" iyy="0.00082" iyz="0" izz="0.00015"/>
      </inertial>
      <visual name="Glass.003">
        <origin xyz="0 0 0" rpy="0 0 0"/>
        <geometry>
          <mesh filename="package://Kitchen_standard/meshes/dae/Glass.007.dae" scale="1.0 1.0 1.0"/>
        </geometry>
        <material name="Glass"/>
      </visual>
      <collision name="Glass.col.003">
        <origin xyz="0 0 0" rpy="0 0 0"/>
        <geometry>
          <mesh filename="package://Kitchen_standard/meshes/dae/Glass.006.dae" scale="1.0 1.0 1.0"/>
        </geometry>
      </collision>
    </link>

    <link name="Microwave_door">
      <inertial>
        <origin xyz="0 0 0" rpy="0 0 0"/>
        <mass value="1.0"/>
        <inertia ixx="0.08548" ixy="-0.00096" ixz="-0.0011" iyy="0.03395" iyz="-0.03158" izz="0.05174"/>
      </inertial>
      <visual name="Door">
        <origin xyz="0 0 0" rpy="0 0 0"/>
        <geometry>
          <mesh filename="package://Kitchen_standard/meshes/dae/meshId0_name.dae" scale="1.0 1.0 1.0"/>
        </geometry>
        <material name="MicrowaveOven"/>
      </visual>
      <collision name="Door">
        <origin xyz="0.00615 0.19801 0.16466" rpy="0 0 0"/>
        <geometry>
          <box size="0.02938 0.41796 0.32349"/>
        </geometry>
      </collision>
    </link>

    <link name="Microwave_root">
      <inertial>
        <origin xyz="0 0 0" rpy="0 0 0"/>
        <mass value="15.0"/>
        <inertia ixx="0.43564" ixy="0.00033" ixz="-0.02819" iyy="0.25701" iyz="-0.00109" izz="0.45276"/>
      </inertial>
      <visual name="Oven">
        <origin xyz="0 0 0" rpy="0 0 0"/>
        <geometry>
          <mesh filename="package://Kitchen_standard/meshes/dae/meshId2_name.dae" scale="1.0 1.0 1.0"/>
        </geometry>
        <material name="MicrowaveOven"/>
      </visual>
      <collision name="Oven.col">
        <origin xyz="0 0 0" rpy="0 0 0"/>
        <geometry>
          <mesh filename="package://Kitchen_standard/meshes/dae/meshId2_name.001.dae" scale="1.0 1.0 1.0"/>
        </geometry>
      </collision>
    </link>

    <link name="Plate">
      <inertial>
        <origin xyz="2e-05 1e-05 0.00484" rpy="0 0 0"/>
        <mass value="1.0"/>
        <inertia ixx="0.00397" ixy="0" ixz="0" iyy="0.00397" iyz="0" izz="0.00794"/>
      </inertial>
      <visual name="Microwave_plate_g.col">
        <origin xyz="0 0 0" rpy="0 0 0"/>
        <geometry>
          <mesh filename="package://Kitchen_standard/meshes/dae/meshId1_name.dae" scale="1.0 1.0 1.0"/>
        </geometry>
        <material name="MicrowaveOven"/>
      </visual>
      <collision name="Microwave_plate">
        <origin xyz="2e-05 1e-05 0.00484" rpy="0 0 0"/>
        <geometry>
          <cylinder radius="0.12598" length="0.0063"/>
        </geometry>
      </collision>
    </link>

    <link name="Plate_root">
      <inertial>
        <origin xyz="0 0 0" rpy="0 0 0"/>
        <mass value="0.55"/>
        <inertia ixx="0.00149" ixy="0" ixz="0" iyy="0.00161" iyz="0" izz="0.00309"/>
      </inertial>
      <visual name="Plate">
        <origin xyz="0 0 0" rpy="0 0 0"/>
        <geometry>
          <mesh filename="package://Kitchen_standard/meshes/dae/Plate.dae" scale="1.0 1.0 1.0"/>
        </geometry>
        <material name="ceramic.001"/>
      </visual>
      <collision name="Plate.col">
        <origin xyz="0 0 0" rpy="0 0 0"/>
        <geometry>
          <mesh filename="package://Kitchen_standard/meshes/dae/Plate.001.dae" scale="1.0 1.0 1.0"/>
        </geometry>
      </collision>
    </link>

    <link name="Plate_root.001">
      <inertial>
        <origin xyz="0 0 0" rpy="0 0 0"/>
        <mass value="0.55"/>
        <inertia ixx="0.00149" ixy="0" ixz="0" iyy="0.00161" iyz="0" izz="0.00309"/>
      </inertial>
      <visual name="Plate.001">
        <origin xyz="0 0 0" rpy="0 0 0"/>
        <geometry>
          <mesh filename="package://Kitchen_standard/meshes/dae/Plate.003.dae" scale="1.0 1.0 1.0"/>
        </geometry>
        <material name="ceramic.001"/>
      </visual>
      <collision name="Plate.col.001">
        <origin xyz="0 0 0" rpy="0 0 0"/>
        <geometry>
          <mesh filename="package://Kitchen_standard/meshes/dae/Plate.002.dae" scale="1.0 1.0 1.0"/>
        </geometry>
      </collision>
    </link>

    <link name="Plate_root.002">
      <inertial>
        <origin xyz="0 0 0" rpy="0 0 0"/>
        <mass value="0.55"/>
        <inertia ixx="0.00149" ixy="0" ixz="0" iyy="0.00161" iyz="0" izz="0.00309"/>
      </inertial>
      <visual name="Plate.002">
        <origin xyz="0 0 0" rpy="0 0 0"/>
        <geometry>
          <mesh filename="package://Kitchen_standard/meshes/dae/Plate.004.dae" scale="1.0 1.0 1.0"/>
        </geometry>
        <material name="ceramic.001"/>
      </visual>
      <collision name="Plate.col.002">
        <origin xyz="0 0 0" rpy="0 0 0"/>
        <geometry>
          <mesh filename="package://Kitchen_standard/meshes/dae/Plate.005.dae" scale="1.0 1.0 1.0"/>
        </geometry>
      </collision>
    </link>

    <link name="Plate_root.003">
      <inertial>
        <origin xyz="0 0 0" rpy="0 0 0"/>
        <mass value="0.55"/>
        <inertia ixx="0.00149" ixy="0" ixz="0" iyy="0.00161" iyz="0" izz="0.00309"/>
      </inertial>
      <visual name="Plate.003">
        <origin xyz="0 0 0" rpy="0 0 0"/>
        <geometry>
          <mesh filename="package://Kitchen_standard/meshes/dae/Plate.007.dae" scale="1.0 1.0 1.0"/>
        </geometry>
        <material name="ceramic.001"/>
      </visual>
      <collision name="Plate.col.003">
        <origin xyz="0 0 0" rpy="0 0 0"/>
        <geometry>
          <mesh filename="package://Kitchen_standard/meshes/dae/Plate.006.dae" scale="1.0 1.0 1.0"/>
        </geometry>
      </collision>
    </link>

    <link name="Plate_root.004">
      <inertial>
        <origin xyz="0 0 0" rpy="0 0 0"/>
        <mass value="0.55"/>
        <inertia ixx="0.00149" ixy="0" ixz="0" iyy="0.00161" iyz="0" izz="0.00309"/>
      </inertial>
      <visual name="Plate.004">
        <origin xyz="0 0 0" rpy="0 0 0"/>
        <geometry>
          <mesh filename="package://Kitchen_standard/meshes/dae/Plate.008.dae" scale="1.0 1.0 1.0"/>
        </geometry>
        <material name="ceramic.001"/>
      </visual>
      <collision name="Plate.col.004">
        <origin xyz="0 0 0" rpy="0 0 0"/>
        <geometry>
          <mesh filename="package://Kitchen_standard/meshes/dae/Plate.009.dae" scale="1.0 1.0 1.0"/>
        </geometry>
      </collision>
    </link>

    <link name="Plate_root.005">
      <inertial>
        <origin xyz="0 0 0" rpy="0 0 0"/>
        <mass value="0.55"/>
        <inertia ixx="0.00149" ixy="0" ixz="0" iyy="0.00161" iyz="0" izz="0.00309"/>
      </inertial>
      <visual name="Plate.005">
        <origin xyz="0 0 0" rpy="0 0 0"/>
        <geometry>
          <mesh filename="package://Kitchen_standard/meshes/dae/Plate.011.dae" scale="1.0 1.0 1.0"/>
        </geometry>
        <material name="ceramic.001"/>
      </visual>
      <collision name="Plate.col.005">
        <origin xyz="0 0 0" rpy="0 0 0"/>
        <geometry>
          <mesh filename="package://Kitchen_standard/meshes/dae/Plate.010.dae" scale="1.0 1.0 1.0"/>
        </geometry>
      </collision>
    </link>

    <link name="SodaCan_root">
      <inertial>
        <origin xyz="0 0 0" rpy="0 0 0"/>
        <mass value="0.384"/>
        <inertia ixx="0.00096" ixy="0" ixz="0" iyy="0.00096" iyz="0" izz="0.0002"/>
      </inertial>
      <visual name="SodaCan">
        <origin xyz="0 0 0" rpy="0 0 0"/>
        <geometry>
          <mesh filename="package://Kitchen_standard/meshes/dae/SodaCan.dae" scale="1.0 1.0 1.0"/>
        </geometry>
        <material name="Material.001"/>
      </visual>
      <collision name="SodaCan">
        <origin xyz="0 0 0.03217" rpy="3.14159 0 0"/>
        <geometry>
          <cylinder radius="0.03285" length="0.11973"/>
        </geometry>
      </collision>
    </link>

    <link name="SquarePlate_root">
      <inertial>
        <origin xyz="0 0 0" rpy="0 0 0"/>
        <mass value="0.9"/>
        <inertia ixx="0.00658" ixy="0" ixz="2e-05" iyy="0.00716" iyz="0" izz="0.01372"/>
      </inertial>
      <visual name="SquarePlate">
        <origin xyz="0 0 0" rpy="0 0 0"/>
        <geometry>
          <mesh filename="package://Kitchen_standard/meshes/dae/Plane.000.dae" scale="1.0 1.0 1.0"/>
        </geometry>
        <material name="ceramic.000"/>
      </visual>
      <collision name="SquarePlate.col">
        <origin xyz="0 0 0" rpy="0 0 0"/>
        <geometry>
          <mesh filename="package://Kitchen_standard/meshes/dae/Plane.004.dae" scale="1.0 1.0 1.0"/>
        </geometry>
      </collision>
    </link>

    <link name="SquarePlate_root.001">
      <inertial>
        <origin xyz="0 0 0" rpy="0 0 0"/>
        <mass value="0.9"/>
        <inertia ixx="0.00658" ixy="0" ixz="2e-05" iyy="0.00716" iyz="0" izz="0.01372"/>
      </inertial>
      <visual name="SquarePlate.001">
        <origin xyz="0 0 0" rpy="0 0 0"/>
        <geometry>
          <mesh filename="package://Kitchen_standard/meshes/dae/Plane.006.dae" scale="1.0 1.0 1.0"/>
        </geometry>
        <material name="ceramic.000"/>
      </visual>
      <collision name="SquarePlate.col.001">
        <origin xyz="0 0 0" rpy="0 0 0"/>
        <geometry>
          <mesh filename="package://Kitchen_standard/meshes/dae/Plane.005.dae" scale="1.0 1.0 1.0"/>
        </geometry>
      </collision>
    </link>

    <link name="SquarePlate_root.002">
      <inertial>
        <origin xyz="0 0 0" rpy="0 0 0"/>
        <mass value="0.9"/>
        <inertia ixx="0.00658" ixy="0" ixz="2e-05" iyy="0.00716" iyz="0" izz="0.01372"/>
      </inertial>
      <visual name="SquarePlate.002">
        <origin xyz="0 0 0" rpy="0 0 0"/>
        <geometry>
          <mesh filename="package://Kitchen_standard/meshes/dae/Plane.007.dae" scale="1.0 1.0 1.0"/>
        </geometry>
        <material name="ceramic.000"/>
      </visual>
      <collision name="SquarePlate.col.002">
        <origin xyz="0 0 0" rpy="0 0 0"/>
        <geometry>
          <mesh filename="package://Kitchen_standard/meshes/dae/Plane.008.dae" scale="1.0 1.0 1.0"/>
        </geometry>
      </collision>
    </link>

    <link name="WineBottle_root">
      <inertial>
        <origin xyz="0 0 0" rpy="0 0 0"/>
        <mass value="1.2"/>
        <inertia ixx="0.02584" ixy="0" ixz="0" iyy="0.02584" iyz="0" izz="0.00113"/>
      </inertial>
      <visual name="WineBottle">
        <origin xyz="0 0 0" rpy="0 0 0"/>
        <geometry>
          <mesh filename="package://Kitchen_standard/meshes/dae/WineBottle.dae" scale="1.0 1.0 1.0"/>
        </geometry>
        <material name="Material.000"/>
      </visual>
      <collision name="WineBottle.col">
        <origin xyz="0 0 0" rpy="0 0 0"/>
        <geometry>
          <mesh filename="package://Kitchen_standard/meshes/dae/WineBottle.001.dae" scale="1.0 1.0 1.0"/>
        </geometry>
      </collision>
    </link>

    <link name="base_link">
      <inertial>
        <origin xyz="0 0 0" rpy="0 0 0"/>
        <mass value="0.2"/>
        <inertia ixx="0.001" ixy="0" ixz="0" iyy="0.001" iyz="0" izz="0.001"/>
      </inertial>
      <visual name="mug_base">
        <origin xyz="0 0 0" rpy="0 0 0"/>
        <geometry>
          <mesh filename="package://Kitchen_standard/meshes/dae/Group1/mesh6/mesh6-geometry#mesh6-geometry.dae" scale="1.0 1.0 1.0"/>
        </geometry>
        <material name="material_0_0.001"/>
      </visual>
      <collision name="mug_base.col">
        <origin xyz="0 0 0" rpy="0 0 0"/>
        <geometry>
          <mesh filename="package://Kitchen_standard/meshes/dae/Group1/mesh6/mesh6-geometry#mesh6-geometry.001.dae" scale="1.0 1.0 1.0"/>
        </geometry>
      </collision>
    </link>

    <link name="lid_link">
      <inertial>
        <origin xyz="0 0 0" rpy="0 0 0"/>
        <mass value="0.001"/>
        <inertia ixx="0.001" ixy="0" ixz="0" iyy="0.001" iyz="0" izz="0.001"/>
      </inertial>
      <visual name="mug_lid">
        <origin xyz="-0.00559 -0.00117 0" rpy="0 0 0"/>
        <geometry>
          <mesh filename="package://Kitchen_standard/meshes/dae/Union1/mesh32/mesh32-geometry#mesh32-geometry.dae" scale="1.0 1.0 1.0"/>
        </geometry>
        <material name="material_0_0.005"/>
      </visual>
      <collision name="mug_lid.col">
        <origin xyz="-0.00559 -0.00117 0" rpy="0 0 0"/>
        <geometry>
          <mesh filename="package://Kitchen_standard/meshes/dae/Union1/mesh32/mesh32-geometry#mesh32-geometry.001.dae" scale="1.0 1.0 1.0"/>
        </geometry>
      </collision>
    </link>

    <link name="mug1_root">
      <inertial>
        <origin xyz="0 0 0" rpy="0 0 0"/>
        <mass value="0.001"/>
        <inertia ixx="0.001" ixy="0" ixz="0" iyy="0.001" iyz="0" izz="0.001"/>
      </inertial>
    </link>

    <link name="refridge_door1">
      <inertial>
        <origin xyz="0 0 0" rpy="0 0 0"/>
        <mass value="0.001"/>
        <inertia ixx="0.001" ixy="0" ixz="0" iyy="0.001" iyz="0" izz="0.001"/>
      </inertial>
      <visual name="Plane">
        <origin xyz="-0.01745 0.4139 0" rpy="0 0 0"/>
        <geometry>
          <mesh filename="package://Kitchen_standard/meshes/dae/Plane.dae" scale="0.02785 0.43052 0.43052"/>
        </geometry>
        <material name="refridge_mat"/>
      </visual>
      <collision name="Plane.col">
        <origin xyz="-0.01745 0.4139 0" rpy="0 0 0"/>
        <geometry>
          <mesh filename="package://Kitchen_standard/meshes/dae/Plane.002.dae" scale="1.0 1.0 1.0"/>
        </geometry>
      </collision>
    </link>

    <link name="refridge_door2">
      <inertial>
        <origin xyz="0 0 0" rpy="0 0 0"/>
        <mass value="0.001"/>
        <inertia ixx="0.001" ixy="0" ixz="0" iyy="0.001" iyz="0" izz="0.001"/>
      </inertial>
      <visual name="Plane.001">
        <origin xyz="-0.01778 0.41381 0" rpy="0 0 0"/>
        <geometry>
          <mesh filename="package://Kitchen_standard/meshes/dae/Plane.001.dae" scale="0.02785 0.43052 0.43052"/>
        </geometry>
        <material name="refridge_mat"/>
      </visual>
      <collision name="Plane.001.000">
        <origin xyz="-0.01778 0.41381 0" rpy="0 0 0"/>
        <geometry>
          <mesh filename="package://Kitchen_standard/meshes/dae/Plane.003.dae" scale="1.0 1.0 1.0"/>
        </geometry>
      </collision>
    </link>

    <link name="refridge_root">
      <inertial>
        <origin xyz="0 0 0" rpy="0 0 0"/>
        <mass value="0.001"/>
        <inertia ixx="0.001" ixy="0" ixz="0" iyy="0.001" iyz="0" izz="0.001"/>
      </inertial>
      <visual name="Cube">
        <origin xyz="0 0 0" rpy="0 0 3.14159"/>
        <geometry>
          <mesh filename="package://Kitchen_standard/meshes/dae/Cube.050.dae" scale="1.0 1.0 1.0"/>
        </geometry>
        <material name="refridge_mat"/>
      </visual>
      <collision name="Cube.col">
        <origin xyz="0 0 0" rpy="0 0 3.14159"/>
        <geometry>
          <mesh filename="package://Kitchen_standard/meshes/dae/Cube.052.dae" scale="1.0 1.0 1.0"/>
        </geometry>
      </collision>
    </link>

    <link name="root_standard">
      <inertial>
        <origin xyz="0 0 0" rpy="0 0 0"/>
        <mass value="0.001"/>
        <inertia ixx="0.001" ixy="0" ixz="0" iyy="0.001" iyz="0" izz="0.001"/>
      </inertial>
    </link>

    <joint name="GlassBottle_root" type="floating">
      <origin xyz="0.00875 -2.11094 0.00633" rpy="0 0 0"/>
      <parent link="root_standard"/>
      <child link="GlassBottle_root"/>
      <limit effort="0" velocity="0"/>
    </joint>

    <joint name="Glass_root" type="floating">
      <origin xyz="0.3044 -1.72322 0.01007" rpy="0 0 0"/>
      <parent link="root_standard"/>
      <child link="Glass_root"/>
      <limit effort="0" velocity="0"/>
    </joint>

    <joint name="Glass_root.001" type="floating">
      <origin xyz="-0.96726 -2.0449 0.01007" rpy="0 0 0"/>
      <parent link="root_standard"/>
      <child link="Glass_root.001"/>
      <limit effort="0" velocity="0"/>
    </joint>

    <joint name="Glass_root.002" type="floating">
      <origin xyz="-1.3204 0.37472 0.13386" rpy="0 0 0"/>
      <parent link="root_standard"/>
      <child link="Glass_root.002"/>
      <limit effort="0" velocity="0"/>
    </joint>

    <joint name="Glass_root.003" type="floating">
      <origin xyz="-1.67462 1.41922 0.13386" rpy="0 0 0"/>
      <parent link="root_standard"/>
      <child link="Glass_root.003"/>
      <limit effort="0" velocity="0"/>
    </joint>

    <joint name="Microwave_door" type="revolute">
      <origin xyz="0.15691 -0.25071 -0.16141" rpy="0 0 0"/>
      <parent link="Microwave_root"/>
      <child link="Microwave_door"/>
      <axis xyz="0 0 1.0"/>
      <limit lower="-6.0" upper="0" effort="0" velocity="0"/>
    </joint>

    <joint name="Microwave_plate" type="continuous">
      <origin xyz="-0.00652 -0.04798 -0.11425" rpy="0 0 0"/>
      <parent link="Microwave_root"/>
      <child link="Plate"/>
      <axis xyz="0 0 1.0"/>
      <limit effort="0" velocity="0"/>
    </joint>

    <joint name="Microwave_root" type="fixed">
      <origin xyz="0.90703 -1.66064 0.14872" rpy="0 0 2.43466"/>
      <parent link="root_standard"/>
      <child link="Microwave_root"/>
    </joint>

    <joint name="Plate_root" type="floating">
      <origin xyz="0.7362 0.14678 -0.00911" rpy="0 0 0"/>
      <parent link="root_standard"/>
      <child link="Plate_root"/>
      <limit effort="0" velocity="0"/>
    </joint>

    <joint name="Plate_root.001" type="floating">
      <origin xyz="0.84973 -0.08917 -0.00911" rpy="0 0 0"/>
      <parent link="root_standard"/>
      <child link="Plate_root.001"/>
      <limit effort="0" velocity="0"/>
    </joint>

    <joint name="Plate_root.002" type="floating">
      <origin xyz="0.9784 1.0172 -0.00911" rpy="0 0 0"/>
      <parent link="root_standard"/>
      <child link="Plate_root.002"/>
      <limit effort="0" velocity="0"/>
    </joint>

    <joint name="Plate_root.003" type="floating">
      <origin xyz="0.78918 1.65299 -0.00911" rpy="0 0 0"/>
      <parent link="root_standard"/>
      <child link="Plate_root.003"/>
      <limit effort="0" velocity="0"/>
    </joint>

    <joint name="Plate_root.004" type="floating">
      <origin xyz="0.76647 -1.05667 -0.00911" rpy="0 0 0"/>
      <parent link="root_standard"/>
      <child link="Plate_root.004"/>
      <limit effort="0" velocity="0"/>
    </joint>

    <joint name="Plate_root.005" type="floating">
      <origin xyz="-1.28469 0.99449 0.13768" rpy="0 0 0"/>
      <parent link="root_standard"/>
      <child link="Plate_root.005"/>
      <limit effort="0" velocity="0"/>
    </joint>

    <joint name="SodaCan_root" type="floating">
      <origin xyz="-0.43468 -2.00379 0.0189" rpy="0 0 0"/>
      <parent link="root_standard"/>
      <child link="SodaCan_root"/>
      <limit effort="0" velocity="0"/>
    </joint>

    <joint name="SquarePlate_root" type="floating">
      <origin xyz="1.17802 0.00141 -0.00907" rpy="0 0 -0.13965"/>
      <parent link="root_standard"/>
      <child link="SquarePlate_root"/>
      <limit effort="0" velocity="0"/>
    </joint>

    <joint name="SquarePlate_root.001" type="floating">
      <origin xyz="-0.10112 -1.88324 -0.00907" rpy="0 0 -2.78146"/>
      <parent link="root_standard"/>
      <child link="SquarePlate_root.001"/>
      <limit effort="0" velocity="0"/>
    </joint>

    <joint name="SquarePlate_root.002" type="floating">
      <origin xyz="-1.58462 -0.01373 0.11953" rpy="0 0 -0.50103"/>
      <parent link="root_standard"/>
      <child link="SquarePlate_root.002"/>
      <limit effort="0" velocity="0"/>
    </joint>

    <joint name="WineBottle_root" type="floating">
      <origin xyz="1.34931 2.03025 -0.0003" rpy="0 0 0"/>
      <parent link="root_standard"/>
      <child link="WineBottle_root"/>
      <limit effort="0" velocity="0"/>
    </joint>

    <joint name="joint_0" type="fixed">
      <origin xyz="0.00559 0.00117 0" rpy="0 0 0"/>
      <parent link="base_link"/>
      <child link="lid_link"/>
    </joint>

    <joint name="joint_1" type="fixed">
      <origin xyz="0 0 0" rpy="0 0 0"/>
      <parent link="mug1_root"/>
      <child link="base_link"/>
    </joint>

    <joint name="mug1_root" type="fixed">
      <origin xyz="0.90549 -0.43287 0.07086" rpy="0 0 0"/>
      <parent link="root_standard"/>
      <child link="mug1_root"/>
    </joint>

    <joint name="refridge_door1" type="revolute">
      <origin xyz="0.35564 0.41796 -0.84106" rpy="0 0 3.14159"/>
      <parent link="refridge_root"/>
      <child link="refridge_door1"/>
      <axis xyz="0 0 1.0"/>
      <limit lower="0" upper="3.0" effort="0" velocity="0"/>
    </joint>

    <joint name="refridge_door2" type="revolute">
      <origin xyz="0.35532 0.41778 0.35533" rpy="0 0 3.14159"/>
      <parent link="refridge_root"/>
      <child link="refridge_door2"/>
      <axis xyz="0 0 1.0"/>
      <limit lower="0" upper="3.0" effort="0" velocity="0"/>
    </joint>

    <joint name="refridge_root" type="fixed">
      <origin xyz="1.02464 2.83296 -0.09375" rpy="0 0 -3.14159"/>
      <parent link="root_standard"/>
      <child link="refridge_root"/>
    </joint>

    <material name="Glass">
      <color rgba="0.8 0.8 0.8 0.040000000000000036"/>
    </material>

    <material name="Material.000">
      <color rgba="0.54216 0.54216 0.54216 1.0"/>
    </material>

    <material name="Material.001">
      <color rgba="0.64 0.64 0.64 1.0"/>
    </material>

    <material name="MicrowaveOven">
      <color rgba="0.8 0.8 0.8 1.0"/>
    </material>

    <material name="__Blue_Glass_">
      <color rgba="0.39216 0.58431 0.92941 0.49804000000000004"/>
    </material>

    <material name="ceramic.000">
      <color rgba="0.64 0.64 0.64 1.0"/>
    </material>

    <material name="ceramic.001">
      <color rgba="0.64 0.64 0.64 1.0"/>
    </material>

    <material name="material_0_0.001">
      <color rgba="0 0 0.4 1.0"/>
    </material>

    <material name="material_0_0.005">
      <color rgba="0.04706 0.04706 0.04706 1.0"/>
    </material>

    <material name="refridge_mat">
      <color rgba="0.74096 0.7879 0.7879 1.0"/>
    </material>

  </robot>
